Workbook

Sheet Cover
A1: EMBECTA CORP. (EMBC): HIGH-YIELD CREDIT MODEL
A2: Three-statement model with a tranche-level debt schedule and base, downside and stress cases. Built from SEC filings.
A4: Analyst | B4: Ohm Patel
A5: Date | B5: 46318
A6: Issuer | B6: Embecta Corp. (Nasdaq: EMBC)
A7: Fiscal year end | B7: 30 September
A8: Ratings | B8: S&P B / stable (cut from B+ on 11 May 2026). Moody's B3 per research brief, not yet verified at source.
A9: Instrument analysed | B9: 5.00% senior secured notes due 15 Feb 2030 ($500m, 1L, pari with TLB/revolver/6.75% notes). CUSIP: confirm on FINRA TRACE.
A10: Recommendation | B10: Buy in moderate size: 5.00% senior secured notes due Feb 2030 at about 81 (proxy price, ~12.1% yield to maturity).
A11: Thesis (1 sentence) | B11: In the downside the company still covers cash interest 2.1x, stays under the 4.75x covenant and refinances; in stress, first-lien recovery of about 59-85 cents limits the loss.
A12: Thesis breaks if | B12: Gross margin about 1.2 points below the downside path (~50% by FY28), equal to covenant EBITDA under ~$213m in FY28.
A13: Data as of | B13: Q3 FY26 10-Q (30 Jun 2026). Refresh when the FY26 10-K lands (late Nov 2026).
A15: KEY METRICS | B15: LTM Jun-26 | C15: Base | D15: Downside | E15: Stress | F15: Note
A16: Credit EBITDA (LTM / trough FY26-30) | B16: =Credit!H6 -> 306 | C16: =Scenarios!B15 -> 279.00253 | D16: =Scenarios!C15 -> 178.53106 | E16: =Scenarios!D15 -> 114.73269
A17: Net leverage (LTM / peak) | B17: =Credit!H17 -> 4.0885621 | C17: =Scenarios!B18 -> 4.1313159 | D17: =Scenarios!C18 -> 4.8042181 | E17: =Scenarios!D18 -> 8.5317224 | F17: Net debt / Credit EBITDA
A18: Net leverage at FY2028E (pre-refinancing) | C18: =Scenarios!B17 -> 3.2382191 | D18: =Scenarios!C17 -> 4.8042181 | E18: =Scenarios!D17 -> 6.8321709 | F18: What lenders see when the term loan has to be refinanced
A19: Covenant-proxy net leverage (LTM / peak) | B19: =Credit!H19 -> 3.7763356 | C19: =Scenarios!B19 -> 3.8656364 | D19: =Scenarios!C19 -> 4.4120371 | E19: =Scenarios!D19 -> 7.5279903 | F19: Limit 4.75x
A20: Interest coverage (LTM / trough) | B20: =Credit!H24 -> 3.1644261 | C20: =Scenarios!B20 -> 3.2923091 | D20: =Scenarios!C20 -> 2.099122 | E20: =Scenarios!D20 -> 1.7478489 | F20: Credit EBITDA / cash interest
A21: Cumulative FCF FY26-30 | C21: =Scenarios!B22 -> 773.56215 | D21: =Scenarios!C22 -> 531.89604 | E21: =Scenarios!D22 -> 387.33254
A22: Total debt FY2030E | B22: =Credit!H8 -> 1469.3 | C22: =Scenarios!B23 -> 801.83785 | D22: =Scenarios!C23 -> 1043.504 | E22: =Scenarios!D23 -> 978.86746 | F22: LTM column = Jun-26 principal
A23: Largest funding shortfall | C23: =Scenarios!B25 -> 0 | D23: =Scenarios!C25 -> 0 | E23: =Scenarios!D25 -> 1178.8675 | F23: Cash needed beyond cash + revolver
A24: 1L recovery at trough | C24: =Scenarios!B26 -> 1 | D24: =Scenarios!C26 -> 1 | E24: =Scenarios!D26 -> 0.58604814 | F24: Distressed EV / net debt (all 1L)
A26: 5.00% notes yield to maturity at proxy price | B26: =Credit!B61 -> 0.12131281 | C26: =Credit!B57 -> 81 | D26: price (proxy; replace with TRACE)
A27: Model integrity | B27: =Checks!B42 -> ALL CHECKS OK
A28: Active scenario | B28: =Scenarios!B4 -> Base
A30: LEGEND
A31: Blue text | B31: Hardcoded input, typed from a filing or set on Drivers
A32: Black text | B32: Formula; do not overwrite
A33: Green text | B33: Link from another tab; do not overwrite
A34: Yellow fill | B34: The scenario toggle and the sensitivity overlay
A35: Interest convention | B35: Calculated on BEGINNING-of-period debt. Kills circularity. Iterative calc stays OFF.
A36: Sign convention | B36: Costs, capex and debt repayment POSITIVE on IS/Debt; cash outflows NEGATIVE on the cash flow statement.
A37: Units | B37: $ millions unless the row says otherwise. Fiscal years end 30 September.
A38: EBITDA definition | B38: Credit EBITDA = EBIT + D&A + non-recurring other opex - asset-sale gains. SBC is NOT added back.
A39: Scenario snapshot | B39: Base / Downside / Stress columns are values pasted from three full recalculations. Re-run by changing Scenarios!B3.

Sheet Scenarios
A1: SCENARIO TOGGLE
A3: Active scenario (1/2/3) | B3: 1
A4: Reads as | B4: =CHOOSE(B3,"Base","Downside","Stress") -> Base
A6: 1 = Base | B6: Management's FY26 guidance midpoint; US decline slows to mid-single digits; cost-out holds margins near 23%; maturities refinanced at 9%.
A7: 2 = Downside | B7: Faster GLP-1/AID substitution, continued price concessions and private-label share loss; margins compress; refinancing at 11%.
A8: 3 = Stress | B8: Downside plus deeper erosion, and the market is shut in FY29-FY30: the Dec-28 revolver, Mar-29 term loan and Feb-30 notes must be repaid from cash.
A10: Changing B3 reprices every ACTIVE row on Drivers, which flows through Model, Debt, Credit and Checks.
A12: SCENARIO SNAPSHOT (values) | B12: Base | C12: Downside | D12: Stress | H12: Live (active)
A13: FY2027E revenue | B13: 1042.3309 | C13: 986.952 | D13: 944.72341 | H13: =Credit!B40 -> 1042.3309
A14: FY2030E revenue | B14: 1033.3427 | C14: 870.88324 | D14: 764.8846 | H14: =Credit!B41 -> 1033.3427
A15: Trough Credit EBITDA (FY26-30) | B15: 279.00253 | C15: 178.53106 | D15: 114.73269 | H15: =Credit!B42 -> 279.00253
A16: FY2030E Credit EBITDA | B16: 279.00253 | C16: 178.53106 | D16: 114.73269 | H16: =Credit!B43 -> 279.00253
A17: Net leverage at FY2028E (the refinancing year-end) | B17: 3.2382191 | C17: 4.8042181 | D17: 6.8321709 | H17: =Credit!B44 -> 3.2382191
A18: Peak net leverage | B18: 4.1313159 | C18: 4.8042181 | D18: 8.5317224 | H18: =Credit!B45 -> 4.1313159
A19: Peak covenant-proxy net leverage | B19: 3.8656364 | C19: 4.4120371 | D19: 7.5279903 | H19: =Credit!B46 -> 3.8656364
A20: Trough interest coverage | B20: 3.2923091 | C20: 2.099122 | D20: 1.7478489 | H20: =Credit!B47 -> 3.2923091
A21: Trough (EBITDA - capex) / interest | B21: 3.0721422 | C21: 1.8431315 | D21: 1.4830233 | H21: =Credit!B48 -> 3.0721422
A22: Cumulative FCF FY26-30 | B22: 773.56215 | C22: 531.89604 | D22: 387.33254 | H22: =Credit!B49 -> 773.56215
A23: Total debt FY2030E | B23: 801.83785 | C23: 1043.504 | D23: 978.86746 | H23: =Credit!B50 -> 801.83785
A24: Minimum year-end liquidity | B24: 410 | C24: 410 | D24: 0 | H24: =Credit!B51 -> 410
... A26: 1L recovery at trough | B26: 1 | C26: 1 | D26: 0.58604814 | H26: =Credit!B53 -> 1
A27: First year not OK | B27: None | C27: None | D27: FY27E COVENANT BREACH | H27: =Credit!B54 -> None
A28: Snapshot pasted as values after recalculating each scenario (26 Oct 2026). Column H is live for whichever scenario B3 selects.
A30: THESIS-BREAK SEARCH (values)
A31: Gross margin cut (pts, FY27-30) that takes BASE to the 4.75x covenant | B31: -0.062841797
A32: Gross margin cut (pts, FY27-30) that takes DOWNSIDE to the 4.75x covenant | B32: -0.011621094
A33: Gross margin cut (pts, FY27-30) that takes DOWNSIDE below 2.0x interest cover | B33: -0.0059570312
A40: SENSITIVITY OVERLAY
A41: Gross margin overlay, FY27-FY30 (pts) | B41: 0 | C41: Leave at 0.0% for the scenarios as written. Enter e.g. -3.0% to cut gross margin by 3 points in every year from FY27 (lost manufacturing leverage beyond the scenario).

Sheet Drivers
A1: DRIVERS: all forecast assumptions
A2: Blue = input. Each driver: an ACTIVE row (black, picks the scenario via Scenarios!$B$3) and Base / Downside / Stress input rows. Nothing is hardcoded anywhere else.
A4: Driver | B4: Scenario | C4: FY2026E | D4: FY2027E | E4: FY2028E | F4: FY2029E | G4: FY2030E | H4: Source / rationale
A5: REVENUE: US pen needles split into volume, price and share drivers
A6: US insulin-pen user volume growth | B6: ACTIVE | C6: =CHOOSE(Scenarios!$B$3,C7,C8,C9) -> -0.06 | D6: =CHOOSE(Scenarios!$B$3,D7,D8,D9) -> -0.05 | E6: =CHOOSE(Scenarios!$B$3,E7,E8,E9) -> -0.05 | F6: =CHOOSE(Scenarios!$B$3,F7,F8,F9) -> -0.045 | G6: =CHOOSE(Scenarios!$B$3,G7,G8,G9) -> -0.04 | H6: Fewer injected-insulin users and injections: GLP-1s delaying/replacing T2D basal-bolus insulin, AID pump adoption in T1D (no pen needles), and the shift to lower-cost retail channels after the IRA Part D redesign. S&P (11 May 2026) cites all four. FY26 set so total revenue hits guidance midpoint.
A7: US insulin-pen user volume growth | B7: Base | C7: -0.06 | D7: -0.05 | E7: -0.05 | F7: -0.045 | G7: -0.04
A8: US insulin-pen user volume growth | B8: Downside | C8: -0.06 | D8: -0.08 | E8: -0.08 | F8: -0.07 | G8: -0.06
A9: US insulin-pen user volume growth | B9: Stress | C9: -0.06 | D9: -0.1 | E9: -0.1 | F9: -0.09 | G9: -0.08
A11: US net price (customer and payer mix) | B11: ACTIVE | C11: =CHOOSE(Scenarios!$B$3,C12,C13,C14) -> -0.05 | D11: =CHOOSE(Scenarios!$B$3,D12,D13,D14) -> -0.04 | E11: =CHOOSE(Scenarios!$B$3,E12,E13,E14) -> -0.03 | F11: =CHOOSE(Scenarios!$B$3,F12,F13,F14) -> -0.02 | G11: =CHOOSE(Scenarios!$B$3,G12,G13,G14) -> -0.02 | H11: Q3 FY26 call: customer and payer mix had a larger effect on net pricing than in Q2; ~$20m unfavorable price in Q3 alone. Part D plans now carry more of the insulin cost, so they push hard for the cheapest needle.
A12: US net price | B12: Base | C12: -0.05 | D12: -0.04 | E12: -0.03 | F12: -0.02 | G12: -0.02
A13: US net price | B13: Downside | C13: -0.05 | D13: -0.06 | E13: -0.05 | F13: -0.04 | G13: -0.03
A14: US net price | B14: Stress | C14: -0.05 | D14: -0.08 | E14: -0.06 | F14: -0.05 | G14: -0.04
A16: US share change (customer wins and losses) | B16: ACTIVE | C16: =CHOOSE(Scenarios!$B$3,C17,C18,C19) -> -0.088 | D16: =CHOOSE(Scenarios!$B$3,D17,D18,D19) -> -0.04 | E16: =CHOOSE(Scenarios!$B$3,E17,E18,E19) -> 0 | F16: =CHOOSE(Scenarios!$B$3,F17,F18,F19) -> 0 | G16: =CHOOSE(Scenarios!$B$3,G17,G18,G19) -> 0 | H16: S&P: a large US retail customer moved to a lower-cost alternative and a lower-cost provider took share at another large customer. Base annualises the FY26 loss into FY27, then holds share. Downside/Stress assume further private-label erosion.
A17: US share change | B17: Base | C17: -0.088 | D17: -0.04 | E17: 0 | F17: 0 | G17: 0
A18: US share change | B18: Downside | C18: -0.095 | D18: -0.06 | E18: -0.03 | F18: -0.02 | G18: -0.02
A19: US share change | B19: Stress | C19: -0.1 | D19: -0.08 | E19: -0.05 | F19: -0.03 | G19: -0.03
A21: International (ex-Owen Mumford) growth | B21: ACTIVE | C21: =CHOOSE(Scenarios!$B$3,C22,C23,C24) -> 0.035 | D21: =CHOOSE(Scenarios!$B$3,D22,D23,D24) -> 0.03 | E21: =CHOOSE(Scenarios!$B$3,E22,E23,E24) -> 0.03 | F21: =CHOOSE(Scenarios!$B$3,F22,F23,F24) -> 0.025 | G21: =CHOOSE(Scenarios!$B$3,G22,G23,G24) -> 0.025 | H21: 9M FY26 Intl ex-OM +3.8% reported (+3.6% adj cc incl. OM). Generic GLP-1 B2B launches co-packaged with Embecta needles (India, Canada, Brazil) and EM syringes, offset by China softness and BD contract-manufacturing insourcing.
A22: International | B22: Base | C22: 0.035 | D22: 0.03 | E22: 0.03 | F22: 0.025 | G22: 0.025
A23: International | B23: Downside | C23: 0.03 | D23: 0.01 | E23: 0.01 | F23: 0 | G23: 0
A24: International | B24: Stress | C24: 0.028 | D24: -0.01 | E24: -0.02 | F24: -0.02 | G24: -0.02
A26: Owen Mumford revenue ($mm) | B26: ACTIVE | C26: =CHOOSE(Scenarios!$B$3,C27,C28,C29) -> 34 | D26: =CHOOSE(Scenarios!$B$3,D27,D28,D29) -> 95 | E26: =CHOOSE(Scenarios!$B$3,E27,E28,E29) -> 103 | F26: =CHOOSE(Scenarios!$B$3,F27,F28,F29) -> 112 | G26: =CHOOSE(Scenarios!$B$3,G27,G28,G29) -> 120 | H26: Closed 15 May 2026; $13.8m revenue in 1.5 months (10-Q Note 3). Pro forma 9M revenue +$54.6m pre-close => ~$90m annual run-rate. Guide: M&A adds 2.9-3.4% to FY26 growth (~$31-37m). Aidaptus auto-injector growth is the GLP-1-positive leg.
A27: Owen Mumford revenue | B27: Base | C27: 34 | D27: 95 | E27: 103 | F27: 112 | G27: 120
A28: Owen Mumford revenue | B28: Downside | C28: 32 | D28: 85 | E28: 88 | F28: 90 | G28: 92
A29: Owen Mumford revenue | B29: Stress | C29: 30 | D29: 80 | E29: 80 | F29: 80 | G29: 80
A31: COST STRUCTURE (reported lines; COGS and SG&A include D&A and SBC as filed)
A32: Gross margin % | B32: ACTIVE | C32: =CHOOSE(Scenarios!$B$3,C33,C34,C35) -> 0.578 | D32: =CHOOSE(Scenarios!$B$3,D33,D34,D35) -> 0.555 | E32: =CHOOSE(Scenarios!$B$3,E33,E34,E35) -> 0.55 | F32: =CHOOSE(Scenarios!$B$3,F33,F34,F35) -> 0.545 | G32: =CHOOSE(Scenarios!$B$3,G33,G34,G35) -> 0.54 | H32: FY25 62.6%; 9M FY26 58.7%; Q3 FY26 56.4%. FY26E set so EBITDA + SBC (~$318m) is consistent with the 23.5-24.0% adj. operating margin guide. Lost manufacturing leverage on falling US volume, lower-margin OM mix. S&P sees adj margin -800bp in FY26.
A33: Gross margin % | B33: Base | C33: 0.578 | D33: 0.555 | E33: 0.55 | F33: 0.545 | G33: 0.54
A34: Gross margin % | B34: Downside | C34: 0.575 | D34: 0.53 | E34: 0.515 | F34: 0.505 | G34: 0.495
A35: Gross margin % | B35: Stress | C35: 0.573 | D35: 0.51 | E35: 0.49 | F35: 0.475 | G35: 0.46
A37: SG&A % of revenue | B37: ACTIVE | C37: =CHOOSE(Scenarios!$B$3,C38,C39,C40) -> 0.308 | D37: =CHOOSE(Scenarios!$B$3,D38,D39,D40) -> 0.3 | E37: =CHOOSE(Scenarios!$B$3,E38,E39,E40) -> 0.295 | F37: =CHOOSE(Scenarios!$B$3,F38,F39,F40) -> 0.29 | G37: =CHOOSE(Scenarios!$B$3,G38,G39,G40) -> 0.29 | H37: FY25 30.7%; 9M FY26 30.8%. Base assumes cost-out after separation from BD is complete; Downside/Stress assume cuts lag revenue.
A38: SG&A % of revenue | B38: Base | C38: 0.308 | D38: 0.3 | E38: 0.295 | F38: 0.29 | G38: 0.29
A39: SG&A % of revenue | B39: Downside | C39: 0.308 | D39: 0.31 | E39: 0.31 | F39: 0.31 | G39: 0.31
A40: SG&A % of revenue | B40: Stress | C40: 0.31 | D40: 0.32 | E40: 0.325 | F40: 0.33 | G40: 0.33
A42: R&D % of revenue | B42: ACTIVE | C42: =CHOOSE(Scenarios!$B$3,C43,C44,C45) -> 0.021 | D42: =CHOOSE(Scenarios!$B$3,D43,D44,D45) -> 0.022 | E42: =CHOOSE(Scenarios!$B$3,E43,E44,E45) -> 0.022 | F42: =CHOOSE(Scenarios!$B$3,F43,F44,F45) -> 0.022 | G42: =CHOOSE(Scenarios!$B$3,G43,G44,G45) -> 0.022 | H42: 9M FY26 2.1% after the patch pump program was discontinued (FY25 3.5%, FY24 7.0%).
A43: R&D % of revenue | B43: Base | C43: 0.021 | D43: 0.022 | E43: 0.022 | F43: 0.022 | G43: 0.022
A44: R&D % of revenue | B44: Downside | C44: 0.021 | D44: 0.022 | E44: 0.022 | F44: 0.022 | G44: 0.022
A45: R&D % of revenue | B45: Stress | C45: 0.021 | D45: 0.022 | E45: 0.022 | F45: 0.022 | G45: 0.022
A47: Other operating expense, non-recurring ($mm) | B47: ACTIVE | C47: =CHOOSE(Scenarios!$B$3,C48,C49,C50) -> 47.9 | D47: =CHOOSE(Scenarios!$B$3,D48,D49,D50) -> 15 | E47: =CHOOSE(Scenarios!$B$3,E48,E49,E50) -> 5 | F47: =CHOOSE(Scenarios!$B$3,F48,F49,F50) -> 5 | G47: =CHOOSE(Scenarios!$B$3,G48,G49,G50) -> 5 | H47: 9M FY26 gross $37.9m (separation $9.6m, cloud amort $7.8m, acquisition $16.9m, other $3.6m) + ~$10m Q4. Added back to Credit EBITDA but paid in cash, so FCF carries it.
A48: Other operating expense, non-recurring | B48: Base | C48: 47.9 | D48: 15 | E48: 5 | F48: 5 | G48: 5
A49: Other operating expense, non-recurring | B49: Downside | C49: 47.9 | D49: 15 | E49: 5 | F49: 5 | G49: 5
...

Sheet Historicals
A1: HISTORICALS: as reported ($mm)
A2: Typed from 10-K and 10-Q filings (EDGAR). Blue = as reported. Black = subtotal formula. Reported totals are re-entered and tied on Checks.
A4: INCOME STATEMENT | B4: FY2023A | C4: FY2024A | D4: FY2025A | E4: 9M FY25A | F4: 9M FY26A | G4: LTM Jun-26 | H4: Source (filing, statement)
A5: Revenue | B5: 1120.8 | C5: 1123.1 | D5: 1080.4 | E5: 816.4 | F5: 754.7 | G5: =D5-E5+F5 -> 1018.7 | H5: Consolidated Statements of Income: FY25 10-K (filed 25 Nov 2025, acc. 0001872789-25-000036) (R3); Q3 FY26 10-Q (filed 7 Aug 2026, acc. 0001872789-26-000033) (R2)
A6: Cost of products sold | B6: 370.9 | C6: 387.9 | D6: 403.6 | E6: 298.1 | F6: 311.9 | G6: =D6-E6+F6 -> 417.4 | H6: Same. Includes depreciation (D&A is not broken out of COGS/SG&A).
A7: Gross profit | B7: =B5-B6 -> 749.9 | C7: =C5-C6 -> 735.2 | D7: =D5-D6 -> 676.8 | E7: =E5-E6 -> 518.3 | F7: =F5-F6 -> 442.8 | G7: =G5-G6 -> 601.3
A8: Selling and administrative | B8: 341.3 | C8: 365.1 | D8: 332 | E8: 245.1 | F8: 232.4 | G8: =D8-E8+F8 -> 319.3 | H8: Includes stock-based compensation.
A9: Research and development | B9: 85.2 | C9: 78.8 | D9: 37.3 | E9: 32.7 | F9: 15.6 | G9: =D9-E9+F9 -> 20.2 | H9: Patch pump program discontinued Nov 2024.
A10: Other operating expense (gross of gains) | B10: 99.4 | C10: 124.5 | D10: 65.4 | E10: 54.9 | F10: 37.9 | G10: =D10-E10+F10 -> 48.4 | H10: FY: separation, cloud amortization, patch pump, severance (10-K Note 5, R53). 9M FY26 = reported $27.8m net + $10.1m gain shown below.
A11: Impairment expense | B11: 2.5 | C11: 0 | D11: 0 | E11: 0 | F11: 0 | G11: =D11-E11+F11 -> 0 | H11: FY23 only on the face of the income statement.
A12: Gain on sale of assets | B12: 0 | C12: 0 | D12: 0 | E12: 0 | F12: 10.1 | G12: =D12-E12+F12 -> 10.1 | H12: 9M FY26: patch pump IP / long-lived assets (10-Q cash flow statement).
A13: Operating income (EBIT) | B13: =B7-B8-B9-B10-B11+B12 -> 221.5 | C13: =C7-C8-C9-C10-C11+C12 -> 166.8 | D13: =D7-D8-D9-D10-D11+D12 -> 242.1 | E13: =E7-E8-E9-E10-E11+E12 -> 185.6 | F13: =F7-F8-F9-F10-F11+F12 -> 167 | G13: =G7-G8-G9-G10-G11+G12 -> 223.5
A14: Interest expense, net | B14: 107 | C14: 112.3 | D14: 107.3 | E14: 81.2 | F14: 70.6 | G14: =D14-E14+F14 -> 96.7 | H14: Shown positive. Net of interest income on cash.
A15: Other income / (expense), net | B15: -8.8 | C15: -10.3 | D15: 1.5 | E15: 2.9 | F15: -0.4 | G15: =D15-E15+F15 -> -1.8
A16: Pretax income | B16: =B13-B14+B15 -> 105.7 | C16: =C13-C14+C15 -> 44.2 | D16: =D13-D14+D15 -> 136.3 | E16: =E13-E14+E15 -> 107.3 | F16: =F13-F14+F15 -> 96 | G16: =G13-G14+G15 -> 125
A17: Income tax provision / (benefit) | B17: 35.3 | C17: -34.1 | D17: 40.9 | E17: 38.3 | F17: 34.9 | G17: =D17-E17+F17 -> 37.5 | H17: FY24 benefit from deferred tax asset recognition.
A18: Net income | B18: =B16-B17 -> 70.4 | C18: =C16-C17 -> 78.3 | D18: =D16-D17 -> 95.4 | E18: =E16-E17 -> 69 | F18: =F16-F17 -> 61.1 | G18: =G16-G17 -> 87.5
A19: Net income as reported (tie) | B19: 70.4 | C19: 78.3 | D19: 95.4 | E19: 69 | F19: 61.1 | G19: =D19-E19+F19 -> 87.5 | H19: Re-entered from the filing; tied on Checks.
A21: EBITDA BUILD: add-backs and the reasoning
A22: D&A (cash flow statement) | B22: 32.6 | C22: 36.2 | D22: 40.7 | E22: 27.6 | F22: 31.1 | G22: =D22-E22+F22 -> 44.2 | H22: Cash flow statements.
A23: Stock-based compensation | B23: 21.5 | C23: 26.3 | D23: 31.6 | E23: 22.1 | F23: 15.8 | G23: =D23-E23+F23 -> 25.3 | H23: Cash flow statements.
A24: CREDIT EBITDA = EBIT + D&A + other opex + impairment - gains | B24: =B13+B22+B10+B11-B12 -> 356 | C24: =C13+C22+C10+C11-C12 -> 327.5 | D24: =D13+D22+D10+D11-D12 -> 348.2 | E24: =E13+E22+E10+E11-E12 -> 268.1 | F24: =F13+F22+F10+F11-F12 -> 225.9 | G24: =G13+G22+G10+G11-G12 -> 306
A25: Credit EBITDA margin | B25: =IFERROR(B24/B5,0) -> 0.31763026 | C25: =IFERROR(C24/C5,0) -> 0.2916036 | D25: =IFERROR(D24/D5,0) -> 0.32228804 | E25: =IFERROR(E24/E5,0) -> 0.32839294 | F25: =IFERROR(F24/F5,0) -> 0.29932423 | G25: =IFERROR(G24/G5,0) -> 0.30038284
A26: Covenant-proxy EBITDA = Credit EBITDA + SBC | B26: =B24+B23 -> 377.5 | C26: =C24+C23 -> 353.8 | D26: =D24+D23 -> 379.8 | E26: =E24+E23 -> 290.2 | F26: =F24+F23 -> 241.7 | G26: =G24+G23 -> 331.3
A27: Management adjusted EBITDA (as reported) | D27: 415.3 | E27: 325.4 | F27: 247.5 | G27: =D27-E27+F27 -> 337.4 | H27: Q3 FY26 earnings release (8-K exhibit 99.1) reconciliation; FY25 per FY25 earnings release.
A28: Add-backs: other operating expense is separation/stand-up, patch pump exit, acquisition and cloud-computing amortization (amortization of capitalised software, D&A-like). I do NOT add back SBC in Credit EBITDA (it is a real cost to owners) and I strip out the $10.1m asset-sale gain. Management additionally adds back SBC and other items, which is why its EBITDA runs ~$30m higher.
A30: REVENUE DISAGGREGATION | B30: FY2023A | C30: FY2024A | D30: FY2025A | E30: 9M FY25A | F30: 9M FY26A | G30: LTM Jun-26 | H30: Source
A31: United States | B31: 601.4 | C31: 607.2 | D31: 579.1 | E31: 437.1 | F31: 347.1 | G31: =D31-E31+F31 -> 489.1 | H31: Geographic revenue: FY25 10-K (filed 25 Nov 2025, acc. 0001872789-25-000036) (R56); Q3 FY26 10-Q (filed 7 Aug 2026, acc. 0001872789-26-000033) (R54)
A32: International (incl. Owen Mumford from 15 May 26) | B32: 519.4 | C32: 515.9 | D32: 501.3 | E32: 379.3 | F32: 407.6 | G32: =D32-E32+F32 -> 529.6 | H32: Same. 9M FY26 includes $13.8m of Owen Mumford revenue.
A33: of which Owen Mumford | B33: 0 | C33: 0 | D33: 0 | E33: 0 | F33: 13.8 | G33: =D33-E33+F33 -> 13.8 | H33: 10-Q Note 3 (acquisition).
A34: Total | B34: =B31+B32 -> 1120.8 | C34: =C31+C32 -> 1123.1 | D34: =D31+D32 -> 1080.4 | E34: =E31+E32 -> 816.4 | F34: =F31+F32 -> 754.7 | G34: =G31+G32 -> 1018.7
A35: US growth y/y | C35: =C31/B31-1 -> 0.0096441636 | D35: =D31/C31-1 -> -0.046277997 | F35: =F31/E31-1 -> -0.20590254
A36: Pen needles | B36: 829.2 | C36: 844.4 | D36: 784.1 | E36: 596.3 | F36: 517.6 | G36: =D36-E36+F36 -> 705.4 | H36: Product family revenue: FY25 10-K (filed 25 Nov 2025, acc. 0001872789-25-000036) (R57); Q3 FY26 10-Q (filed 7 Aug 2026, acc. 0001872789-26-000033) (R55)
A37: Syringes | B37: 138.1 | C37: 126.2 | D37: 124.6 | E37: 92.3 | F37: 93.7 | G37: =D37-E37+F37 -> 126
A38: Safety | B38: 126.3 | C38: 129.4 | D38: 137.8 | E38: 103.2 | F38: 108.3 | G38: =D38-E38+F38 -> 142.9
A39: Other | B39: 14.2 | C39: 10.3 | D39: 14 | E39: 9.9 | F39: 23.2 | G39: =D39-E39+F39 -> 27.3
A40: Contract manufacturing | B40: 13 | C40: 12.8 | D40: 19.9 | E40: 14.7 | F40: 11.9 | G40: =D40-E40+F40 -> 17.1 | H40: Mostly BD, which is insourcing.
A41: Pen needle growth y/y | C41: =C36/B36-1 -> 0.018330921 | D41: =D36/C36-1 -> -0.071411653 | F41: =F36/E36-1 -> -0.13198055
A43: BALANCE SHEET | B43: 30-Sep-23 | C43: 30-Sep-24 | D43: 30-Sep-25 | F43: 30-Jun-26 | H43: Source
A44: Cash, equivalents & restricted cash | B44: 326.5 | C44: 274.2 | D44: 228.6 | F44: 218.2 | H44: Balance sheets: FY24 10-K (filed 11 Dec 2024, acc. 0001872789-24-000037) (R5, FY23); FY25 10-K (filed 25 Nov 2025, acc. 0001872789-25-000036) (R5); Q3 FY26 10-Q (filed 7 Aug 2026, acc. 0001872789-26-000033) (R4). Cash + restricted cash, to tie to the cash flow statement.
...

Sheet Debt
A1: DEBT SCHEDULE ($mm)
A2: Tranche terms from the FY25 10-K and Q3 FY26 10-Q debt notes and the 6 Aug 2026 First Amendment (subsequent event). All four instruments are senior secured first lien, pari passu.
A4: Tranche | B4: 30-Sep-25 | C4: 30-Jun-26 | D4: Rate type | E4: Coupon / spread | F4: SOFR floor | G4: Maturity | H4: Maturity FY | I4: Commitment | J4: Source
A5: Term Loan B | B5: 716.8 | C5: 639.4 | D5: SOFR + | E5: 0.03 | F5: 0.005 | G5: 47208 | H5: 2029 | J5: R71 (10-K) / R66 (10-Q). $950m original, 0.25%/qtr amortization, SOFR+300bp, 0.50% floor (R65).
A6: 5.00% senior secured notes | B6: 500 | C6: 500 | D6: Fixed | E6: 0.05 | G6: 47529 | H6: 2030 | J6: Issued 10 Feb 2022, due 15 Feb 2030 (8-K 10 Feb 2022). Non-call to 15 Feb 2027.
A7: 6.75% senior secured notes | B7: 200 | C7: 200 | D7: Fixed | E7: 0.0675 | G7: 47529 | H7: 2030 | J7: Due 15 Feb 2030 (10-Q debt note; Cbonds RegS listing EMBC 6.75 02/15/30).
A8: Revolver tranche 1 (non-extended) | D8: SOFR + | E8: 0.03 | F8: 0.005 | G8: 46477 | H8: 2027 | I8: 100 | J8: First Amendment 6 Aug 2026 (10-Q Note 21 / Ex. 10.2): $100m stays due 31 Mar 2027, 0.25% fee.
A9: Revolver tranche 2 (extended) | D9: SOFR + | E9: 0.035 | F9: 0.005 | G9: 47117 | H9: 2029 | I9: 210 | J9: Extended to 30 Dec 2028 at SOFR+350bp, 0.375% fee (Ex. 10.2). Total commitments cut from $500m to $310m.
A10: Revolver drawn (total) | B10: 0 | C10: 129.9 | D10: SOFR + | J10: Drawn $180m to fund Owen Mumford; repaid $50.1m. Tranche split of drawings not disclosed; modelled at the tranche-2 spread.
A11: TOTAL PRINCIPAL | B11: =B5+B6+B7+B10 -> 1416.8 | C11: =C5+C6+C7+C10 -> 1469.3 | I11: =I8+I9 -> 310
A12: Reported total principal (tie) | B12: 1416.8 | C12: 1469.3 | J12: 10-K R71: $1,416.8m; 10-Q R66: $1,469.3m.
A13: Unamortized issuance costs & discounts | B13: 18.6 | C13: 14.2 | J13: Netted against debt on the balance sheet.
A14: Revolver commitment at 30-Sep-25 (pre-amendment) | B14: 500 | J14: Original $500m facility, March 2027 maturity (10-K).
A15: TLB mandatory amortization per year | B15: 9.5 | J15: 0.25% of $950m per quarter = $9.5m a year (R65).
A16: Level 2 fair value of debt / carrying value | B16: 1186.2 | C16: 1455.1 | D16: =B16/C16 -> 0.8152017 | J16: 10-Q R65. ~81.5 cents blended across all tranches: the market-price proxy without Bloomberg.
A18: ROLL-FORWARD (fiscal years ending 30 Sep) | B18: FY2025A | C18: FY2026E | D18: FY2027E | E18: FY2028E | F18: FY2029E | G18: FY2030E
A19: Fiscal year | B19: 2025 | C19: =B19+1 -> 2026 | D19: =C19+1 -> 2027 | E19: =D19+1 -> 2028 | F19: =E19+1 -> 2029 | G19: =F19+1 -> 2030
A20: Revolver capacity
A21: Revolver commitments at year end | B21: =B14 -> 500 | C21: =IF(C$19<$H$8,$I$8,0)+IF(OR(C$19<$H$9,Drivers!C$129=1),$I$9,0) -> 310 | D21: =IF(D$19<$H$8,$I$8,0)+IF(OR(D$19<$H$9,Drivers!D$129=1),$I$9,0) -> 210 | E21: =IF(E$19<$H$8,$I$8,0)+IF(OR(E$19<$H$9,Drivers!E$129=1),$I$9,0) -> 210 | F21: =IF(F$19<$H$8,$I$8,0)+IF(OR(F$19<$H$9,Drivers!F$129=1),$I$9,0) -> 210 | G21: =IF(G$19<$H$8,$I$8,0)+IF(OR(G$19<$H$9,Drivers!G$129=1),$I$9,0) -> 210 | J21: Tranche 1 gone after Mar-27; tranche 2 after Dec-28 unless refinanced (Drivers refi flag).
A22: Cash available for debt service
A23: Cash before debt service (Model) | C23: =Model!C71 -> 185.16435 | D23: =Model!D71 -> 351.70522 | E23: =Model!E71 -> 359.18826 | F23: =Model!F71 -> 363.85194 | G23: =Model!G71 -> 355.05238
A24: Less: TLB mandatory amortization | C24: =-C36 -> -9.5 | D24: =-D36 -> -9.5 | E24: =-E36 -> -9.5 | F24: =-F36 -> -9.5 | G24: =-G36 -> 0
A25: Less: maturities NOT refinanced | C25: =-(C37+C42+C46)*(1-Drivers!C$129) -> 0 | D25: =-(D37+D42+D46)*(1-Drivers!D$129) -> 0 | E25: =-(E37+E42+E46)*(1-Drivers!E$129) -> 0 | F25: =-(F37+F42+F46)*(1-Drivers!F$129) -> 0 | G25: =-(G37+G42+G46)*(1-Drivers!G$129) -> 0
A26: Less: forced revolver repayment (commitments shrink) | C26: =-C55 -> 0 | D26: =-D55 -> 0 | E26: =-E55 -> 0 | F26: =-F55 -> 0 | G26: =-G55 -> 0
A27: Cash available | C27: =SUM(C23:C26) -> 175.66435 | D27: =SUM(D23:D26) -> 342.20522 | E27: =SUM(E23:E26) -> 349.68826 | F27: =SUM(F23:F26) -> 354.35194 | G27: =SUM(G23:G26) -> 355.05238
A28: Minimum cash | C28: =Drivers!C$114 -> 200 | D28: =Drivers!D$114 -> 200 | E28: =Drivers!E$114 -> 200 | F28: =Drivers!F$114 -> 200 | G28: =Drivers!G$114 -> 200
A29: Excess / (shortfall) vs minimum | C29: =C27-C28 -> -24.335646 | D29: =D27-D28 -> 142.20522 | E29: =E27-E28 -> 149.68826 | F29: =F27-F28 -> 154.35194 | G29: =G27-G28 -> 155.05238
A30: Revolver draw | C30: =IF(C29<0,MIN(-C29,C21-(C54-C55)),0) -> 24.335646 | D30: =IF(D29<0,MIN(-D29,D21-(D54-D55)),0) -> 0 | E30: =IF(E29<0,MIN(-E29,E21-(E54-E55)),0) -> 0 | F30: =IF(F29<0,MIN(-F29,F21-(F54-F55)),0) -> 0 | G30: =IF(G29<0,MIN(-G29,G21-(G54-G55)),0) -> 0
A31: Revolver repayment | C31: =IF(C29>0,MIN(C29,C54-C55),0) -> 0 | D31: =IF(D29>0,MIN(D29,D54-D55),0) -> 24.335646 | E31: =IF(E29>0,MIN(E29,E54-E55),0) -> 0 | F31: =IF(F29>0,MIN(F29,F54-F55),0) -> 0 | G31: =IF(G29>0,MIN(G29,G54-G55),0) -> 0
A32: Cash swept to term debt | C32: =MAX(0,C29-C31)*Drivers!C$119 -> 0 | D32: =MAX(0,D29-D31)*Drivers!D$119 -> 117.86957 | E32: =MAX(0,E29-E31)*Drivers!E$119 -> 149.68826 | F32: =MAX(0,F29-F31)*Drivers!F$119 -> 154.35194 | G32: =MAX(0,G29-G31)*Drivers!G$119 -> 155.05238
A33: FUNDING SHORTFALL (cash below minimum after revolver) | C33: =MAX(0,-(C29+C30)) -> 0 | D33: =MAX(0,-(D29+D30)) -> 0 | E33: =MAX(0,-(E29+E30)) -> 0 | F33: =MAX(0,-(F29+F30)) -> 0 | G33: =MAX(0,-(G29+G30)) -> 0
A34: Term Loan B (SOFR + 300, floor 0.50%)
A35: Beginning balance | C35: =B39 -> 716.8 | D35: =C39 -> 707.3 | E35: =D39 -> 579.93043 | F35: =E39 -> 420.74217 | G35: =F39 -> 0
A36: Mandatory amortization | C36: =IF(C$19<=$H$5,MIN(C35,$B$15),0) -> 9.5 | D36: =IF(D$19<=$H$5,MIN(D35,$B$15),0) -> 9.5 | E36: =IF(E$19<=$H$5,MIN(E35,$B$15),0) -> 9.5 | F36: =IF(F$19<=$H$5,MIN(F35,$B$15),0) -> 9.5 | G36: =IF(G$19<=$H$5,MIN(G35,$B$15),0) -> 0
A37: Repaid at maturity | C37: =IF(C$19=$H$5,C35-C36,0) -> 0 | D37: =IF(D$19=$H$5,D35-D36,0) -> 0 | E37: =IF(E$19=$H$5,E35-E36,0) -> 0 | F37: =IF(F$19=$H$5,F35-F36,0) -> 411.24217 | G37: =IF(G$19=$H$5,G35-G36,0) -> 0
A38: Optional prepayment from excess cash | C38: =IF(C$19<$H$5,MIN(C32,C35-C36),0) -> 0 | D38: =IF(D$19<$H$5,MIN(D32,D35-D36),0) -> 117.86957 | E38: =IF(E$19<$H$5,MIN(E32,E35-E36),0) -> 149.68826 | F38: =IF(F$19<$H$5,MIN(F32,F35-F36),0) -> 0 | G38: =IF(G$19<$H$5,MIN(G32,G35-G36),0) -> 0
A39: Ending balance | B39: =B5 -> 716.8 | C39: =C35-C36-C37-C38 -> 707.3 | D39: =D35-D36-D37-D38 -> 579.93043 | E39: =E35-E36-E37-E38 -> 420.74217 | F39: =F35-F36-F37-F38 -> 0 | G39: =G35-G36-G37-G38 -> 0
A40: 5.00% senior secured notes due Feb 2030
A41: Beginning balance | C41: =B43 -> 500 | D41: =C43 -> 500 | E41: =D43 -> 500 | F41: =E43 -> 500 | G41: =F43 -> 500
A42: Repaid at maturity | C42: =IF(C$19=$H$6,C41,0) -> 0 | D42: =IF(D$19=$H$6,D41,0) -> 0 | E42: =IF(E$19=$H$6,E41,0) -> 0 | F42: =IF(F$19=$H$6,F41,0) -> 0 | G42: =IF(G$19=$H$6,G41,0) -> 500
...

Sheet Model
A1: FORECAST MODEL ($mm)
A2: Black = formula, green = link to another tab. Change behaviour on Drivers. Column B links to the FY2025A historicals.
B4: FY2025A | C4: FY2026E | D4: FY2027E | E4: FY2028E | F4: FY2029E | G4: FY2030E | H4: Note
A5: REVENUE BUILD
A6: US revenue | B6: =Historicals!D31 -> 579.1 | C6: =B6*(1+Drivers!C$6)*(1+Drivers!C$11)*(1+Drivers!C$16) -> 471.62831 | D6: =C6*(1+Drivers!D$6)*(1+Drivers!D$11)*(1+Drivers!D$16) -> 412.92001 | E6: =D6*(1+Drivers!E$6)*(1+Drivers!E$11)*(1+Drivers!E$16) -> 380.50579 | F6: =E6*(1+Drivers!F$6)*(1+Drivers!F$11)*(1+Drivers!F$16) -> 356.11537 | G6: =F6*(1+Drivers!G$6)*(1+Drivers!G$11)*(1+Drivers!G$16) -> 335.03334 | H6: Prior year x (1 + volume) x (1 + net price) x (1 + share).
A7: US growth | C7: =C6/B6-1 -> -0.185584 | D7: =D6/C6-1 -> -0.12448 | E7: =E6/D6-1 -> -0.0785 | F7: =F6/E6-1 -> -0.0641 | G7: =G6/F6-1 -> -0.0592
A8: International revenue (ex-Owen Mumford) | B8: =Historicals!D32 -> 501.3 | C8: =B8*(1+Drivers!C$21) -> 518.8455 | D8: =C8*(1+Drivers!D$21) -> 534.41086 | E8: =D8*(1+Drivers!E$21) -> 550.44319 | F8: =E8*(1+Drivers!F$21) -> 564.20427 | G8: =F8*(1+Drivers!G$21) -> 578.30938
A9: Owen Mumford revenue | B9: =Historicals!D33 -> 0 | C9: =Drivers!C$26 -> 34 | D9: =Drivers!D$26 -> 95 | E9: =Drivers!E$26 -> 103 | F9: =Drivers!F$26 -> 112 | G9: =Drivers!G$26 -> 120
A10: TOTAL REVENUE | B10: =B6+B8+B9 -> 1080.4 | C10: =C6+C8+C9 -> 1024.4738 | D10: =D6+D8+D9 -> 1042.3309 | E10: =E6+E8+E9 -> 1033.949 | F10: =F6+F8+F9 -> 1032.3196 | G10: =G6+G8+G9 -> 1033.3427
A11: Revenue growth | B11: =Historicals!D5/Historicals!C5-1 -> -0.038019767 | C11: =C10/B10-1 -> -0.051764341 | D11: =D10/C10-1 -> 0.017430483 | E11: =E10/D10-1 -> -0.0080414917 | F11: =F10/E10-1 -> -0.0015758433 | G11: =G10/F10-1 -> 0.0009910465
A12: US share of revenue | B12: =B6/B10 -> 0.53600518 | C12: =C6/C10 -> 0.46036151 | D12: =D6/D10 -> 0.39615061 | E12: =E6/E10 -> 0.36801215 | F12: =F6/F10 -> 0.34496619 | G12: =G6/G10 -> 0.32422287
A13: INCOME STATEMENT
A14: Revenue | B14: =Historicals!D5 -> 1080.4 | C14: =C10 -> 1024.4738 | D14: =D10 -> 1042.3309 | E14: =E10 -> 1033.949 | F14: =F10 -> 1032.3196 | G14: =G10 -> 1033.3427
A15: Cost of products sold | B15: =Historicals!D6 -> 403.6 | C15: =C14*(1-(Drivers!C$32+Scenarios!$B$41*Drivers!C$172)) -> 432.32795 | D15: =D14*(1-(Drivers!D$32+Scenarios!$B$41*Drivers!D$172)) -> 463.83724 | E15: =E14*(1-(Drivers!E$32+Scenarios!$B$41*Drivers!E$172)) -> 465.27704 | F15: =F14*(1-(Drivers!F$32+Scenarios!$B$41*Drivers!F$172)) -> 469.70544 | G15: =G14*(1-(Drivers!G$32+Scenarios!$B$41*Drivers!G$172)) -> 475.33765
A16: Gross profit | B16: =B14-B15 -> 676.8 | C16: =C14-C15 -> 592.14586 | D16: =D14-D15 -> 578.49364 | E16: =E14-E15 -> 568.67194 | F16: =F14-F15 -> 562.61421 | G16: =G14-G15 -> 558.00507
A17: Gross margin (incl. any overlay) | B17: =B16/B14 -> 0.62643465 | C17: =C16/C14 -> 0.578 | D17: =D16/D14 -> 0.555 | E17: =E16/E14 -> 0.55 | F17: =F16/F14 -> 0.545 | G17: =G16/G14 -> 0.54
A18: Selling and administrative | B18: =Historicals!D8 -> 332 | C18: =C14*Drivers!C$37 -> 315.53793 | D18: =D14*Drivers!D$37 -> 312.69926 | E18: =E14*Drivers!E$37 -> 305.01495 | F18: =F14*Drivers!F$37 -> 299.3727 | G18: =G14*Drivers!G$37 -> 299.66939
A19: Research and development | B19: =Historicals!D9 -> 37.3 | C19: =C14*Drivers!C$42 -> 21.51395 | D19: =D14*Drivers!D$42 -> 22.931279 | E19: =E14*Drivers!E$42 -> 22.746878 | F19: =F14*Drivers!F$42 -> 22.711032 | G19: =G14*Drivers!G$42 -> 22.73354
A20: Other operating expense (non-recurring) & impairment | B20: =Historicals!D10+Historicals!D11 -> 65.4 | C20: =Drivers!C$47 -> 47.9 | D20: =Drivers!D$47 -> 15 | E20: =Drivers!E$47 -> 5 | F20: =Drivers!F$47 -> 5 | G20: =Drivers!G$47 -> 5
A21: Gain on sale of assets | B21: =Historicals!D12 -> 0 | C21: =Drivers!C$52 -> 10.1 | D21: =Drivers!D$52 -> 0 | E21: =Drivers!E$52 -> 0 | F21: =Drivers!F$52 -> 0 | G21: =Drivers!G$52 -> 0
A22: Operating income (EBIT) | B22: =B16-B18-B19-B20+B21 -> 242.1 | C22: =C16-C18-C19-C20+C21 -> 217.29398 | D22: =D16-D18-D19-D20+D21 -> 227.86309 | E22: =E16-E18-E19-E20+E21 -> 235.91011 | F22: =F16-F18-F19-F20+F21 -> 235.53048 | G22: =G16-G18-G19-G20+G21 -> 230.60214
A23: Interest expense, net | B23: =Historicals!D14 -> 107.3 | C23: =Debt!C76 -> 89.55 | D23: =Debt!D76 -> 86.517601 | E23: =Debt!E76 -> 73.033152 | F23: =Debt!F76 -> 62.083886 | G23: =Debt!G76 -> 57.507621 | H23: From Debt tab, on beginning balances.
A24: Other income / (expense) | B24: =Historicals!D15 -> 1.5 | C24: =Drivers!C$174 -> 0 | D24: =Drivers!D$174 -> 0 | E24: =Drivers!E$174 -> 0 | F24: =Drivers!F$174 -> 0 | G24: =Drivers!G$174 -> 0
A25: Pretax income | B25: =B22-B23+B24 -> 136.3 | C25: =C22-C23+C24 -> 127.74398 | D25: =D22-D23+D24 -> 141.34549 | E25: =E22-E23+E24 -> 162.87696 | F25: =F22-F23+F24 -> 173.44659 | G25: =G22-G23+G24 -> 173.09452
A26: Income tax | B26: =Historicals!D17 -> 40.9 | C26: =MAX(0,C25*Drivers!C$77) -> 38.323193 | D26: =MAX(0,D25*Drivers!D$77) -> 38.163283 | E26: =MAX(0,E25*Drivers!E$77) -> 43.97678 | F26: =MAX(0,F25*Drivers!F$77) -> 46.83058 | G26: =MAX(0,G25*Drivers!G$77) -> 46.73552
A27: NET INCOME | B27: =B25-B26 -> 95.4 | C27: =C25-C26 -> 89.420784 | D27: =D25-D26 -> 103.18221 | E27: =E25-E26 -> 118.90018 | F27: =F25-F26 -> 126.61601 | G27: =G25-G26 -> 126.359
A28: EBITDA
A29: D&A | B29: =Historicals!D22 -> 40.7 | C29: =C14*Drivers!C$57 -> 43.0279 | D29: =D14*Drivers!D$57 -> 43.777897 | E29: =E14*Drivers!E$57 -> 43.425857 | F29: =F14*Drivers!F$57 -> 43.357425 | G29: =G14*Drivers!G$57 -> 43.400394
A30: of which amortization of intangibles | C30: =Drivers!C$62 -> 2 | D30: =Drivers!D$62 -> 4.5 | E30: =Drivers!E$62 -> 4.5 | F30: =Drivers!F$62 -> 4.5 | G30: =Drivers!G$62 -> 4.5
A31: of which depreciation of PP&E | C31: =C29-C30 -> 41.0279 | D31: =D29-D30 -> 39.277897 | E31: =E29-E30 -> 38.925857 | F31: =F29-F30 -> 38.857425 | G31: =G29-G30 -> 38.900394
A32: CREDIT EBITDA | B32: =B22+B29+B20-B21 -> 348.2 | C32: =C22+C29+C20-C21 -> 298.12188 | D32: =D22+D29+D20-D21 -> 286.64099 | E32: =E22+E29+E20-E21 -> 284.33597 | F32: =F22+F29+F20-F21 -> 283.8879 | G32: =G22+G29+G20-G21 -> 279.00253 | H32: EBIT + D&A + non-recurring other opex - asset-sale gains. No SBC add-back.
A33: Credit EBITDA margin | B33: =B32/B14 -> 0.32228804 | C33: =C32/C14 -> 0.291 | D33: =D32/D14 -> 0.275 | E33: =E32/E14 -> 0.275 | F33: =F32/F14 -> 0.275 | G33: =G32/G14 -> 0.27
A34: Stock-based compensation (inside SG&A) | B34: =Historicals!D23 -> 31.6 | C34: =C14*Drivers!C$67 -> 20.489476 | D34: =D14*Drivers!D$67 -> 20.846618 | E34: =E14*Drivers!E$67 -> 20.67898 | F34: =F14*Drivers!F$67 -> 20.646393 | G34: =G14*Drivers!G$67 -> 20.666854
A35: Covenant-proxy EBITDA (Credit EBITDA + SBC) | B35: =B32+B34 -> 379.8 | C35: =C32+C34 -> 318.61135 | D35: =D32+D34 -> 307.48761 | E35: =E32+E34 -> 305.01495 | F35: =F32+F34 -> 304.53429 | G35: =G32+G34 -> 299.66939
A36: BALANCE SHEET
A37: Cash & restricted cash | B37: =Historicals!D44 -> 228.6 | C37: =C79 -> 200 | D37: =D79 -> 200 | E37: =E79 -> 200 | F37: =F79 -> 200 | G37: =G79 -> 200
A38: Trade receivables | B38: =Historicals!D45 -> 145.6 | C38: =Drivers!C$83/365*C14 -> 182.44054 | D38: =Drivers!D$83/365*D14 -> 177.05346 | E38: =Drivers!E$83/365*E14 -> 175.62969 | F38: =Drivers!F$83/365*F14 -> 175.35293 | G38: =Drivers!G$83/365*G14 -> 175.52671
A39: Inventories | B39: =Historicals!D46 -> 178.6 | C39: =Drivers!C$88/365*C15 -> 236.89203 | D39: =Drivers!D$88/365*D15 -> 241.44952 | E39: =Drivers!E$88/365*E15 -> 235.82535 | F39: =Drivers!F$88/365*F15 -> 231.63556 | G39: =Drivers!G$88/365*G15 -> 234.41309
A40: Prepaid & other current assets | B40: =Historicals!D47 -> 78.6 | C40: =B40+Drivers!C$163 -> 83.8 | D40: =C40+Drivers!D$163 -> 83.8 | E40: =D40+Drivers!E$163 -> 83.8 | F40: =E40+Drivers!F$163 -> 83.8 | G40: =F40+Drivers!G$163 -> 83.8
A41: Total current assets | B41: =SUM(B37:B40) -> 631.4 | C41: =SUM(C37:C40) -> 703.13257 | D41: =SUM(D37:D40) -> 702.30299 | E41: =SUM(E37:E40) -> 695.25504 | F41: =SUM(F37:F40) -> 690.78848 | G41: =SUM(G37:G40) -> 693.7398
...

Sheet Credit
A1: CREDIT METRICS ($mm)
A2: Columns line up with Model and Debt (C = FY2026E). H = last twelve months to 30 Jun 2026, from Historicals and the 10-Q.
A4: Metric | B4: FY2025A | C4: FY2026E | D4: FY2027E | E4: FY2028E | F4: FY2029E | G4: FY2030E | H4: LTM Jun-26 | I4: Note
A5: Inputs
A6: Credit EBITDA | B6: =Model!B32 -> 348.2 | C6: =Model!C32 -> 298.12188 | D6: =Model!D32 -> 286.64099 | E6: =Model!E32 -> 284.33597 | F6: =Model!F32 -> 283.8879 | G6: =Model!G32 -> 279.00253 | H6: =Historicals!G24 -> 306
A7: Covenant-proxy EBITDA (+SBC) | B7: =Model!B35 -> 379.8 | C7: =Model!C35 -> 318.61135 | D7: =Model!D35 -> 307.48761 | E7: =Model!E35 -> 305.01495 | F7: =Model!F35 -> 304.53429 | G7: =Model!G35 -> 299.66939 | H7: =Historicals!G26 -> 331.3
A8: Total debt (principal, all 1L secured, incl. unpaid maturities) | B8: =Debt!B59 -> 1416.8 | C8: =Debt!C59+MAX(0,-Model!C37) -> 1431.6356 | D8: =Debt!D59+MAX(0,-Model!D37) -> 1279.9304 | E8: =Debt!E59+MAX(0,-Model!E37) -> 1120.7422 | F8: =Debt!F59+MAX(0,-Model!F37) -> 956.89023 | G8: =Debt!G59+MAX(0,-Model!G37) -> 801.83785 | H8: =Debt!C11 -> 1469.3 | I8: If a maturity cannot be refinanced or repaid, model cash goes negative; that hole is unpaid debt, so it is added back here.
A9: Cash & restricted cash (floored at zero) | B9: =Model!B37 -> 228.6 | C9: =MAX(0,Model!C37) -> 200 | D9: =MAX(0,Model!D37) -> 200 | E9: =MAX(0,Model!E37) -> 200 | F9: =MAX(0,Model!F37) -> 200 | G9: =MAX(0,Model!G37) -> 200 | H9: =Historicals!F44 -> 218.2
A10: Net debt | B10: =B8-B9 -> 1188.2 | C10: =C8-C9 -> 1231.6356 | D10: =D8-D9 -> 1079.9304 | E10: =E8-E9 -> 920.74217 | F10: =F8-F9 -> 756.89023 | G10: =G8-G9 -> 601.83785 | H10: =H8-H9 -> 1251.1
A11: Cash interest (FY25A / LTM: reported net interest) | B11: =Historicals!D14 -> 107.3 | C11: =Debt!C73 -> 90.551 | D11: =Debt!D73 -> 86.517601 | E11: =Debt!E73 -> 75.533152 | F11: =Debt!F73 -> 65.583886 | G11: =Debt!G73 -> 62.407621 | H11: =Historicals!G14 -> 96.7
A12: Capex | B12: =Model!B64 -> 9.3 | C12: =Model!C64 -> 5.122369 | D12: =Model!D64 -> 20.846618 | E12: =Model!E64 -> 25.848725 | F12: =Model!F64 -> 25.807991 | G12: =Model!G64 -> 25.833568 | H12: =Historicals!G70 -> 9.5
A13: Free cash flow (after interest) | B13: =Model!B65 -> 182.4 | C13: =Model!C65 -> 110.56435 | D13: =Model!D65 -> 160.00522 | E13: =Model!E65 -> 167.48826 | F13: =Model!F65 -> 172.15194 | G13: =Model!G65 -> 163.35238 | H13: =Historicals!G71 -> 164.6
A14: Undrawn revolver commitments | B14: =Debt!B57 -> 500 | C14: =Debt!C57 -> 285.66435 | D14: =Debt!D57 -> 210 | E14: =Debt!E57 -> 210 | F14: =Debt!F57 -> 210 | G14: =Debt!G57 -> 210 | H14: =Debt!I11-Debt!C10 -> 180.1 | I14: LTM column uses post-amendment $310m commitments.
A15: Leverage
A16: Gross leverage (Debt / Credit EBITDA) | B16: =IFERROR(B8/B6,0) -> 4.0689259 | C16: =IFERROR(C8/C6,0) -> 4.8021824 | D16: =IFERROR(D8/D6,0) -> 4.4652735 | E16: =IFERROR(E8/E6,0) -> 3.9416123 | F16: =IFERROR(F8/F6,0) -> 3.3706622 | G16: =IFERROR(G8/G6,0) -> 2.8739447 | H16: =IFERROR(H8/H6,0) -> 4.801634
A17: Net leverage (Net debt / Credit EBITDA) | B17: =IFERROR(B10/B6,0) -> 3.4124067 | C17: =IFERROR(C10/C6,0) -> 4.1313159 | D17: =IFERROR(D10/D6,0) -> 3.7675366 | E17: =IFERROR(E10/E6,0) -> 3.2382191 | F17: =IFERROR(F10/F6,0) -> 2.6661588 | G17: =IFERROR(G10/G6,0) -> 2.1571053 | H17: =IFERROR(H10/H6,0) -> 4.0885621
A18: Secured net leverage (all debt is 1L) | B18: =B17 -> 3.4124067 | C18: =C17 -> 4.1313159 | D18: =D17 -> 3.7675366 | E18: =E17 -> 3.2382191 | F18: =F17 -> 2.6661588 | G18: =G17 -> 2.1571053 | H18: =H17 -> 4.0885621 | I18: No unsecured layer: nothing sits beneath the 1L, so secured and total leverage are the same.
A19: Covenant-proxy net leverage (Net debt / EBITDA + SBC) | B19: =IFERROR(B10/B7,0) -> 3.1284887 | C19: =IFERROR(C10/C7,0) -> 3.8656364 | D19: =IFERROR(D10/D7,0) -> 3.5121104 | E19: =IFERROR(E10/E7,0) -> 3.0186788 | F19: =IFERROR(F10/F7,0) -> 2.4854023 | G19: =IFERROR(G10/G7,0) -> 2.0083394 | H19: =IFERROR(H10/H7,0) -> 3.7763356 | I19: Management cited ~3.7x LTM at Q3 FY26 on its own EBITDA (~$337m).
A20: Covenant maximum | C20: =Drivers!C$149 -> 4.75 | D20: =Drivers!D$149 -> 4.75 | E20: =Drivers!E$149 -> 4.75 | F20: =Drivers!F$149 -> 4.75 | G20: =Drivers!G$149 -> 4.75
A21: EBITDA cushion before covenant breach | C21: =IFERROR(1-(C10/C20)/C7,0) -> 0.18618181 | D21: =IFERROR(1-(D10/D20)/D7,0) -> 0.26060834 | E21: =IFERROR(1-(E10/E20)/E7,0) -> 0.36448867 | F21: =IFERROR(1-(F10/F20)/F7,0) -> 0.47675742 | G21: =IFERROR(1-(G10/G20)/G7,0) -> 0.5771917 | I21: How far covenant EBITDA can fall from the forecast before net leverage hits the limit.
A22: Covenant EBITDA at which the covenant breaches | C22: =C10/C20 -> 259.29171 | D22: =D10/D20 -> 227.35377 | E22: =E10/E20 -> 193.84046 | F22: =F10/F20 -> 159.34531 | G22: =G10/G20 -> 126.70271
A23: Coverage & cash generation
A24: Interest coverage (Credit EBITDA / cash interest) | B24: =IFERROR(B6/B11,0) -> 3.2451072 | C24: =IFERROR(C6/C11,0) -> 3.2923091 | D24: =IFERROR(D6/D11,0) -> 3.3130945 | E24: =IFERROR(E6/E11,0) -> 3.7643864 | F24: =IFERROR(F6/F11,0) -> 4.3286228 | G24: =IFERROR(G6/G11,0) -> 4.4706485 | H24: =IFERROR(H6/H11,0) -> 3.1644261
A25: (EBITDA - capex) / cash interest | B25: =IFERROR((B6-B12)/B11,0) -> 3.1584343 | C25: =IFERROR((C6-C12)/C11,0) -> 3.2357402 | D25: =IFERROR((D6-D12)/D11,0) -> 3.0721422 | E25: =IFERROR((E6-E12)/E11,0) -> 3.4221695 | F25: =IFERROR((F6-F12)/F11,0) -> 3.9351116 | G25: =IFERROR((G6-G12)/G11,0) -> 4.0566995 | H25: =IFERROR((H6-H12)/H11,0) -> 3.0661841
A26: FCF / total debt | B26: =IFERROR(B13/B8,0) -> 0.12874082 | C26: =IFERROR(C13/C8,0) -> 0.077229395 | D26: =IFERROR(D13/D8,0) -> 0.12501087 | E26: =IFERROR(E13/E8,0) -> 0.14944406 | F26: =IFERROR(F13/F8,0) -> 0.17990772 | G26: =IFERROR(G13/G8,0) -> 0.20372246 | H26: =IFERROR(H13/H8,0) -> 0.11202613
A27: Cumulative net debt paydown since FY25 | C27: =Debt!$B$59-C8 -> -14.835646 | D27: =Debt!$B$59-D8 -> 136.86957 | E27: =Debt!$B$59-E8 -> 296.05783 | F27: =Debt!$B$59-F8 -> 459.90977 | G27: =Debt!$B$59-G8 -> 614.96215
A28: Liquidity & maturities
A29: Liquidity (cash + undrawn revolver) | B29: =B9+B14 -> 728.6 | C29: =C9+C14 -> 485.66435 | D29: =D9+D14 -> 410 | E29: =E9+E14 -> 410 | F29: =F9+F14 -> 410 | G29: =G9+G14 -> 410 | H29: =H9+H14 -> 398.3
A30: Principal maturing in the year (incl. amortization) | C30: =Debt!C36+Debt!C37+Debt!C42+Debt!C46+Debt!C55 -> 9.5 | D30: =Debt!D36+Debt!D37+Debt!D42+Debt!D46+Debt!D55 -> 9.5 | E30: =Debt!E36+Debt!E37+Debt!E42+Debt!E46+Debt!E55 -> 9.5 | F30: =Debt!F36+Debt!F37+Debt!F42+Debt!F46+Debt!F55 -> 420.74217 | G30: =Debt!G36+Debt!G37+Debt!G42+Debt!G46+Debt!G55 -> 700
A31: Principal maturing in the NEXT 24 months | C31: =SUM(D30:E30) -> 19 | D31: =SUM(E30:F30) -> 430.24217 | E31: =SUM(F30:G30) -> 1120.7422 | F31: =G30 -> 700 | G31: =0 -> 0 | I31: FY29 column shows FY30 only; FY30 has no forecast year after it.
A32: Liquidity / next-24-month maturities | C32: =IFERROR(C29/C31,0) -> 25.561282 | D32: =IFERROR(D29/D31,0) -> 0.95295168 | E32: =IFERROR(E29/E31,0) -> 0.36582901 | F32: =IFERROR(F29/F31,0) -> 0.58571429 | G32: =IFERROR(G29/G31,0) -> 0
A33: Funding shortfall (Debt tab) | C33: =Debt!C33 -> 0 | D33: =Debt!D33 -> 0 | E33: =Debt!E33 -> 0 | F33: =Debt!F33 -> 0 | G33: =Debt!G33 -> 0
A34: Recovery (all 1L pari passu)
A35: Distressed enterprise value (Credit EBITDA x multiple) | C35: =C6*Drivers!C$154 -> 1788.7313 | D35: =D6*Drivers!D$154 -> 1719.846 | E35: =E6*Drivers!E$154 -> 1706.0158 | F35: =F6*Drivers!F$154 -> 1703.3274 | G35: =G6*Drivers!G$154 -> 1674.0152
A36: 1L recovery if default in this year (EV / net debt) | C36: =IFERROR(MIN(1,C35/C10),0) -> 1 | D36: =IFERROR(MIN(1,D35/D10),0) -> 1 | E36: =IFERROR(MIN(1,E35/E10),0) -> 1 | F36: =IFERROR(MIN(1,F35/F10),0) -> 1 | G36: =IFERROR(MIN(1,G35/G10),0) -> 1 | I36: All debt is pari passu first lien, so every tranche recovers the same cents on the dollar.
A37: Status | C37: =IF(Model!C37<0,"DEFAULT",IF(C19>C20,"COVENANT BREACH","OK")) -> OK | D37: =IF(Model!D37<0,"DEFAULT",IF(D19>D20,"COVENANT BREACH","OK")) -> OK | E37: =IF(Model!E37<0,"DEFAULT",IF(E19>E20,"COVENANT BREACH","OK")) -> OK | F37: =IF(Model!F37<0,"DEFAULT",IF(F19>F20,"COVENANT BREACH","OK")) -> OK | G37: =IF(Model!G37<0,"DEFAULT",IF(G19>G20,"COVENANT BREACH","OK")) -> OK
A39: SUMMARY for the active scenario (feeds the Scenarios snapshot and the Cover)
A40: FY2027E revenue | B40: =Model!D10 -> 1042.3309
A41: FY2030E revenue | B41: =Model!G10 -> 1033.3427
A42: Trough Credit EBITDA (FY26-30) | B42: =MIN(C6:G6) -> 279.00253
...

Sheet Checks
A1: CHECKS: every status should read OK
A4: Check | B4: FY2025A | C4: FY2026E | D4: FY2027E | E4: FY2028E | F4: FY2029E | G4: FY2030E | H4: What it proves
A5: Balance sheet balances (assets - liabilities - equity) | B5: =Model!B45-Model!B53 -> 0 | C5: =Model!C45-Model!C53 -> 0 | D5: =Model!D45-Model!D53 -> 0 | E5: =Model!E45-Model!E53 -> 0 | F5: =Model!F45-Model!F53 -> 0 | G5: =Model!G45-Model!G53 -> 0 | H5: No plug anywhere: the statements are linked.
A6: status | B6: =IF(ABS(B5)<0.05,"OK","FAIL") -> OK | C6: =IF(ABS(C5)<0.05,"OK","FAIL") -> OK | D6: =IF(ABS(D5)<0.05,"OK","FAIL") -> OK | E6: =IF(ABS(E5)<0.05,"OK","FAIL") -> OK | F6: =IF(ABS(F5)<0.05,"OK","FAIL") -> OK | G6: =IF(ABS(G5)<0.05,"OK","FAIL") -> OK
A7: Cash flow ending cash = balance sheet cash | B7: =Model!B79-Model!B37 -> 0 | C7: =Model!C79-Model!C37 -> 0 | D7: =Model!D79-Model!D37 -> 0 | E7: =Model!E79-Model!E37 -> 0 | F7: =Model!F79-Model!F37 -> 0 | G7: =Model!G79-Model!G37 -> 0
A8: status | B8: =IF(ABS(B7)<0.05,"OK","FAIL") -> OK | C8: =IF(ABS(C7)<0.05,"OK","FAIL") -> OK | D8: =IF(ABS(D7)<0.05,"OK","FAIL") -> OK | E8: =IF(ABS(E7)<0.05,"OK","FAIL") -> OK | F8: =IF(ABS(F7)<0.05,"OK","FAIL") -> OK | G8: =IF(ABS(G7)<0.05,"OK","FAIL") -> OK
A9: Debt tab (principal - unamortized costs) = balance sheet debt | B9: =Debt!B59-Debt!B63-Model!B48-Model!B49 -> 0 | C9: =Debt!C59-Debt!C63-Model!C48-Model!C49 -> 0 | D9: =Debt!D59-Debt!D63-Model!D48-Model!D49 -> 0 | E9: =Debt!E59-Debt!E63-Model!E48-Model!E49 -> 0 | F9: =Debt!F59-Debt!F63-Model!F48-Model!F49 -> 0 | G9: =Debt!G59-Debt!G63-Model!G48-Model!G49 -> 0
A10: status | B10: =IF(ABS(B9)<0.05,"OK","FAIL") -> OK | C10: =IF(ABS(C9)<0.05,"OK","FAIL") -> OK | D10: =IF(ABS(D9)<0.05,"OK","FAIL") -> OK | E10: =IF(ABS(E9)<0.05,"OK","FAIL") -> OK | F10: =IF(ABS(F9)<0.05,"OK","FAIL") -> OK | G10: =IF(ABS(G9)<0.05,"OK","FAIL") -> OK
A11: Debt waterfall ending cash = Model ending cash | C11: =Debt!C27+Debt!C30-Debt!C31-Debt!C38-Debt!C51-Model!C37 -> 0 | D11: =Debt!D27+Debt!D30-Debt!D31-Debt!D38-Debt!D51-Model!D37 -> 0 | E11: =Debt!E27+Debt!E30-Debt!E31-Debt!E38-Debt!E51-Model!E37 -> 0 | F11: =Debt!F27+Debt!F30-Debt!F31-Debt!F38-Debt!F51-Model!F37 -> 0 | G11: =Debt!G27+Debt!G30-Debt!G31-Debt!G38-Debt!G51-Model!G37 -> 0 | H11: The sweep logic on Debt and the cash flow statement agree.
A12: status | C12: =IF(ABS(C11)<0.05,"OK","FAIL") -> OK | D12: =IF(ABS(D11)<0.05,"OK","FAIL") -> OK | E12: =IF(ABS(E11)<0.05,"OK","FAIL") -> OK | F12: =IF(ABS(F11)<0.05,"OK","FAIL") -> OK | G12: =IF(ABS(G11)<0.05,"OK","FAIL") -> OK
A13: Revolver within commitments (drawn - commitments, if positive) | C13: =MAX(0,Debt!C56-Debt!C21) -> 0 | D13: =MAX(0,Debt!D56-Debt!D21) -> 0 | E13: =MAX(0,Debt!E56-Debt!E21) -> 0 | F13: =MAX(0,Debt!F56-Debt!F21) -> 0 | G13: =MAX(0,Debt!G56-Debt!G21) -> 0
A14: status | C14: =IF(ABS(C13)<0.05,"OK","FAIL") -> OK | D14: =IF(ABS(D13)<0.05,"OK","FAIL") -> OK | E14: =IF(ABS(E13)<0.05,"OK","FAIL") -> OK | F14: =IF(ABS(F13)<0.05,"OK","FAIL") -> OK | G14: =IF(ABS(G13)<0.05,"OK","FAIL") -> OK
A15: Revenue build = income statement revenue | C15: =Model!C10-Model!C14 -> 0 | D15: =Model!D10-Model!D14 -> 0 | E15: =Model!E10-Model!E14 -> 0 | F15: =Model!F10-Model!F14 -> 0 | G15: =Model!G10-Model!G14 -> 0
A16: status | C16: =IF(ABS(C15)<0.05,"OK","FAIL") -> OK | D16: =IF(ABS(D15)<0.05,"OK","FAIL") -> OK | E16: =IF(ABS(E15)<0.05,"OK","FAIL") -> OK | F16: =IF(ABS(F15)<0.05,"OK","FAIL") -> OK | G16: =IF(ABS(G15)<0.05,"OK","FAIL") -> OK
A17: Opening debt principal ties to 10-K ($1,416.8m) | B17: =Debt!B11-Debt!B12 -> 0
A18: status | B18: =IF(ABS(B17)<0.05,"OK","FAIL") -> OK
A19: Jun-26 debt principal ties to 10-Q ($1,469.3m) | B19: =Debt!C11-Debt!C12 -> 0
A20: status | B20: =IF(ABS(B19)<0.05,"OK","FAIL") -> OK
A22: Historical ties to the filings
B23: FY2023A | C23: FY2024A | D23: FY2025A | E23: 9M FY25A | F23: 9M FY26A
A24: Net income: built from lines vs reported | B24: =Historicals!B18-Historicals!B19 -> 0 | C24: =Historicals!C18-Historicals!C19 -> 0 | D24: =Historicals!D18-Historicals!D19 -> 0 | E24: =Historicals!E18-Historicals!E19 -> 0 | F24: =Historicals!F18-Historicals!F19 -> 0 | H24: Every income statement line is typed correctly.
A25: status | B25: =IF(ABS(B24)<0.05,"OK","FAIL") -> OK | C25: =IF(ABS(C24)<0.05,"OK","FAIL") -> OK | D25: =IF(ABS(D24)<0.05,"OK","FAIL") -> OK | E25: =IF(ABS(E24)<0.05,"OK","FAIL") -> OK | F25: =IF(ABS(F24)<0.05,"OK","FAIL") -> OK
A26: Total assets: built vs reported | B26: =Historicals!B52-Historicals!B53 -> 0 | C26: =Historicals!C52-Historicals!C53 -> 0 | D26: =Historicals!D52-Historicals!D53 -> 0 | F26: =Historicals!F52-Historicals!F53 -> 0
A27: status | B27: =IF(ABS(B26)<0.05,"OK","FAIL") -> OK | C27: =IF(ABS(C26)<0.05,"OK","FAIL") -> OK | D27: =IF(ABS(D26)<0.05,"OK","FAIL") -> OK | F27: =IF(ABS(F26)<0.05,"OK","FAIL") -> OK
A28: Historical balance sheet balances | B28: =Historicals!B52-Historicals!B61 -> 0 | C28: =Historicals!C52-Historicals!C61 -> 0 | D28: =Historicals!D52-Historicals!D61 -> 0 | F28: =Historicals!F52-Historicals!F61 -> 0
A29: status | B29: =IF(ABS(B28)<0.05,"OK","FAIL") -> OK | C29: =IF(ABS(C28)<0.05,"OK","FAIL") -> OK | D29: =IF(ABS(D28)<0.05,"OK","FAIL") -> OK | F29: =IF(ABS(F28)<0.05,"OK","FAIL") -> OK
A30: Ending cash: built from cash flow vs reported | B30: =Historicals!B82-Historicals!B83 -> 0 | C30: =Historicals!C82-Historicals!C83 -> 0 | D30: =Historicals!D82-Historicals!D83 -> 0 | E30: =Historicals!E82-Historicals!E83 -> 0 | F30: =Historicals!F82-Historicals!F83 -> 0 | H30: Every cash flow line is typed correctly.
A31: status | B31: =IF(ABS(B30)<0.05,"OK","FAIL") -> OK | C31: =IF(ABS(C30)<0.05,"OK","FAIL") -> OK | D31: =IF(ABS(D30)<0.05,"OK","FAIL") -> OK | E31: =IF(ABS(E30)<0.05,"OK","FAIL") -> OK | F31: =IF(ABS(F30)<0.05,"OK","FAIL") -> OK
A32: Geographic revenue = total revenue | B32: =Historicals!B34-Historicals!B5 -> 0 | C32: =Historicals!C34-Historicals!C5 -> 0 | D32: =Historicals!D34-Historicals!D5 -> 0 | E32: =Historicals!E34-Historicals!E5 -> 0 | F32: =Historicals!F34-Historicals!F5 -> 0
A33: status | B33: =IF(ABS(B32)<0.05,"OK","FAIL") -> OK | C33: =IF(ABS(C32)<0.05,"OK","FAIL") -> OK | D33: =IF(ABS(D32)<0.05,"OK","FAIL") -> OK | E33: =IF(ABS(E32)<0.05,"OK","FAIL") -> OK | F33: =IF(ABS(F32)<0.05,"OK","FAIL") -> OK
A34: Product revenue = total revenue | B34: =SUM(Historicals!B36:B40)-Historicals!B5 -> 0 | C34: =SUM(Historicals!C36:C40)-Historicals!C5 -> 0 | D34: =SUM(Historicals!D36:D40)-Historicals!D5 -> 0 | E34: =SUM(Historicals!E36:E40)-Historicals!E5 -> 0 | F34: =SUM(Historicals!F36:F40)-Historicals!F5 -> 0
A35: status | B35: =IF(ABS(B34)<0.05,"OK","FAIL") -> OK | C35: =IF(ABS(C34)<0.05,"OK","FAIL") -> OK | D35: =IF(ABS(D34)<0.05,"OK","FAIL") -> OK | E35: =IF(ABS(E34)<0.05,"OK","FAIL") -> OK | F35: =IF(ABS(F34)<0.05,"OK","FAIL") -> OK
A37: Sanity checks (flag, not fail)
A38: FY26E revenue inside guidance ($1,015-1,035m) | B38: 1015 | C38: 1035 | D38: =IF(AND(Model!C10>=B38-5,Model!C10<=C38),"OK","REVIEW") -> OK | H38: Q3 FY26 earnings release guidance. $5m tolerance below the low end for Stress.
A39: Cash never negative (otherwise the scenario is a default) | C39: =IF(Model!C37>=0,"OK","DEFAULT") -> OK | D39: =IF(Model!D37>=0,"OK","DEFAULT") -> OK | E39: =IF(Model!E37>=0,"OK","DEFAULT") -> OK | F39: =IF(Model!F37>=0,"OK","DEFAULT") -> OK | G39: =IF(Model!G37>=0,"OK","DEFAULT") -> OK
A40: Circularity | B40: OK | H40: Interest uses beginning balances; iterative calculation is OFF. No cell references its own result.
A42: MODEL INTEGRITY | B42: =IF(SUMPRODUCT(--((B6:G6)="FAIL"))+SUMPRODUCT(--((B8:G8)="FAIL"))+SUMPRODUCT(--((B10:G10)="FAIL"))+SUMPRODUCT(--((B12:G12)="FAIL"))+SUMPRODUCT(--((B14:G14)="FAIL"))+SUMPRODUCT(--((B16:G16)="FAIL"))+SUMPRODUCT(--((B18:G18)="FAIL"))+SUMPRODUCT(--((B20:G20)="FAIL"))+SUMPRODUCT(--((B25:G25)="FAIL"))+SUMPRODUCT(--((B27:G27)="FAIL"))+SUMPRODUCT(--((B29:G29)="FAIL"))+SUMPRODUCT(--((B31:G31)="FAIL"))+SUMPRODUCT(--((B33:G33)="FAIL"))+SUMPRODUCT(--((B35:G35)="FAIL"))=0,"ALL CHECKS OK","FAIL") -> ALL CHECKS OK
